File: XRD/example/XRD pattern dir/XRD pattern.csv
[Measurement conditions]
Sample identification,
Comment - 1,"Configuration=Chi-Phi-z stage 240mm (reflection), Owner=User-1, Creation date=14/10/2016 10:05:30"
Comment - 2,"Goniometer=Theta/Theta; Minimum step size 2Theta:0.0001; Minimum step size Omega:0.0001"
Comment - 3,"Sample stage=Chi-Phi-z stage 240 mm (reflection); Minimum step size Phi:0.01; Minimum step size Chi:0.01; Minimum step size Z:0.001"
Comment - 4,"Diffractometer system=EMPYREAN"
Comment - 5,"Measurement program=C:\PANalytical\Data Collector\Programs\Celia\Thin film 10 mm mask\GIXRD 30to90deg Omega0,5deg 2,0HrScan.xrdmp, Identifier={107BDB78-2716-4F85-905B-2E5E6B11902F}"
Anode material,Cu
K-Alpha1 wavelength,1.5405980
K-Alpha2 wavelength,1.5444260
Ratio K-Alpha2/K-Alpha1,0.500
Divergence slit,Fixed,0.19mm
Monochromator used,NO
Generator voltage, 45
Tube current, 40
File date and time,04/Mar/2020 14:01
Unit cell,
h k l, 0 0 0
Scan axis,2Theta
Scan range,30.00000,90.00000
Scan step size,0.0200000
No. of points, 3000
Scan type,CONTINUOUS
Omega,0.5000
Phi,0.00
Psi,0.00
Z,0.000
Time per step,2.200
[Scan points]
Angle,Intensity
30.01000,12.0
30.05000,16.0
30.09000,18.0
30.13000,19.0
30.17000,16.0
30.21000,16.0
30.25000,12.0
30.29000,18.0
30.33000,10.0
30.37000,12.0
30.41000,18.0
30.45000,24.0
30.49000,16.0
30.53000,26.0
30.57000,24.0
30.61000,13.0
30.65000,12.0
30.69000,13.0
30.73000,13.0
30.77000,11.0
30.81000,18.0
30.85000,12.0
30.89000,19.0
30.93000,15.0
30.97000,18.0
31.01000,22.0
31.05000,18.0
31.09000,22.0
31.13000,15.0
31.17000,19.0
31.21000,11.0
31.25000,24.0
31.29000,13.0
31.33000,15.0
31.37000,20.0
31.41000,16.0
31.45000,23.0
31.49000,12.0
31.53000,19.0
31.57000,13.0
31.61000,14.0
31.65000,14.0
31.69000,16.0
31.73000,10.0
31.77000,16.0
31.81000,16.0
31.85000,16.0
31.89000,9.0
31.93000,10.0
31.97000,11.0
32.01000,13.0
32.05000,15.0
32.09000,14.0
32.13000,14.0
32.17000,20.0
32.21000,14.0
32.25000,14.0
32.29000,10.0
32.33000,11.0
32.37000,24.0
32.41000,19.0
32.45000,23.0
32.49000,13.0
32.53000,11.0
32.57000,17.0
32.61000,15.0
32.65000,15.0
32.69000,15.0
32.73000,14.0
32.77000,13.0
32.81000,22.0
32.85000,21.0
32.89000,19.0
32.93000,13.0
32.97000,20.0
33.01000,9.0
33.05000,16.0
33.09000,10.0
33.13000,12.0
33.17000,18.0
33.21000,17.0
33.25000,15.0
33.29000,18.0
33.33000,8.0
33.37000,16.0
33.41000,17.0
33.45000,13.0
33.49000,14.0
33.53000,15.0
33.57000,12.0
33.61000,10.0
33.65000,14.0
33.69000,14.0
33.73000,17.0
33.77000,8.0
33.81000,15.0
33.85000,14.0
33.89000,17.0
33.93000,10.0
33.97000,23.0
34.01000,6.0
34.05000,9.0
34.09000,7.0
34.13000,21.0
34.17000,22.0
34.21000,14.0
34.25000,12.0
34.29000,12.0
34.33000,14.0
34.37000,13.0
34.41000,17.0
34.45000,6.0
34.49000,9.0
34.53000,14.0
34.57000,12.0
34.61000,17.0
34.65000,10.0
34.69000,17.0
34.73000,11.0
34.77000,8.0
34.81000,11.0
34.85000,19.0
34.89000,9.0
34.93000,14.0
34.97000,12.0
35.01000,9.0
35.05000,9.0
35.09000,15.0
35.13000,16.0
35.17000,17.0
35.21000,20.0
35.25000,12.0
35.29000,15.0
35.33000,14.0
35.37000,17.0
35.41000,14.0
35.45000,16.0
35.49000,11.0
35.53000,12.0
35.57000,17.0
35.61000,19.0
35.65000,14.0
35.69000,13.0
35.73000,12.0
35.77000,20.0
35.81000,24.0
35.85000,21.0
35.89000,10.0
35.93000,22.0
35.97000,17.0
36.01000,18.0
36.05000,14.0
36.09000,21.0
36.13000,9.0
36.17000,23.0
36.21000,17.0
36.25000,14.0
36.29000,16.0
36.33000,13.0
36.37000,17.0
36.41000,18.0
36.45000,10.0
36.49000,18.0
36.53000,12.0
36.57000,14.0
36.61000,8.0
36.65000,13.0
36.69000,19.0
36.73000,13.0
36.77000,11.0
36.81000,15.0
36.85000,18.0
36.89000,19.0
36.93000,9.0
36.97000,15.0
37.01000,13.0
37.05000,16.0
37.09000,9.0
37.13000,15.0
37.17000,10.0
37.21000,9.0
37.25000,17.0
37.29000,14.0
37.33000,7.0
37.37000,19.0
37.41000,14.0
37.45000,27.0
37.49000,26.0
37.53000,15.0
37.57000,11.0
37.61000,19.0
37.65000,15.0
37.69000,15.0
37.73000,19.0
37.77000,23.0
37.81000,16.0
37.85000,10.0
37.89000,19.0
37.93000,9.0
37.97000,16.0
38.01000,14.0
38.05000,18.0
38.09000,31.0
38.13000,15.0
38.17000,12.0
38.21000,18.0
38.25000,21.0
38.29000,11.0
38.33000,9.0
38.37000,19.0
38.41000,16.0
38.45000,9.0
38.49000,13.0
38.53000,10.0
38.57000,12.0
38.61000,22.0
38.65000,15.0
38.69000,19.0
38.73000,18.0
38.77000,15.0
38.81000,19.0
38.85000,13.0
38.89000,5.0
38.93000,16.0
38.97000,16.0
39.01000,15.0
39.05000,9.0
39.09000,21.0
39.13000,15.0
39.17000,15.0
39.21000,11.0
39.25000,20.0
39.29000,10.0
39.33000,19.0
39.37000,13.0
39.41000,17.0
39.45000,9.0
39.49000,9.0
39.53000,16.0
39.57000,17.0
39.61000,24.0
39.65000,16.0
39.69000,9.0
39.73000,10.0
39.77000,12.0
39.81000,8.0
39.85000,11.0
39.89000,10.0
39.93000,17.0
39.97000,16.0
40.01000,16.0
40.05000,16.0
40.09000,22.0
40.13000,24.0
40.17000,20.0
40.21000,20.0
40.25000,16.0
40.29000,13.0
40.33000,12.0
40.37000,23.0
40.41000,21.0
40.45000,24.0
40.49000,26.0
40.53000,16.0
40.57000,23.0
40.61000,21.0
40.65000,15.0
40.69000,30.0
40.73000,20.0
40.77000,26.0
40.81000,37.0
40.85000,33.0
40.89000,25.0
40.93000,26.0
40.97000,19.0
41.01000,31.0
41.05000,34.0
41.09000,44.0
41.13000,56.0
41.17000,52.0
41.21000,56.0
41.25000,68.0
41.29000,97.0
41.33000,125.0
41.37000,147.0
41.41000,168.0
41.45000,194.0
41.49000,252.0
41.53000,271.0
41.57000,242.0
41.61000,273.0
41.65000,284.0
41.69000,265.0
41.73000,264.0
41.77000,193.0
41.81000,155.0
41.85000,130.0
41.89000,107.0
41.93000,83.0
41.97000,62.0
42.01000,58.0
42.05000,50.0
42.09000,39.0
42.13000,24.0
42.17000,26.0
42.21000,29.0
42.25000,36.0
42.29000,17.0
42.33000,29.0
42.37000,21.0
42.41000,26.0
42.45000,22.0
42.49000,23.0
42.53000,17.0
42.57000,12.0
42.61000,32.0
42.65000,14.0
42.69000,14.0
42.73000,22.0
42.77000,19.0
42.81000,11.0
42.85000,12.0
42.89000,18.0
42.93000,24.0
42.97000,16.0
43.01000,11.0
43.05000,22.0
43.09000,23.0
43.13000,11.0
43.17000,12.0
43.21000,12.0
43.25000,17.0
43.29000,17.0
43.33000,18.0
43.37000,11.0
43.41000,13.0
43.45000,9.0
43.49000,12.0
43.53000,12.0
43.57000,25.0
43.61000,9.0
43.65000,15.0
43.69000,13.0
43.73000,16.0
43.77000,7.0
43.81000,4.0
43.85000,14.0
43.89000,15.0
43.93000,17.0
43.97000,15.0
44.01000,18.0
44.05000,21.0
44.09000,31.0
44.13000,20.0
44.17000,24.0
44.21000,22.0
44.25000,18.0
44.29000,25.0
44.33000,28.0
44.37000,36.0
44.41000,39.0
44.45000,39.0
44.49000,40.0
44.53000,35.0
44.57000,42.0
44.61000,38.0
44.65000,34.0
44.69000,24.0
44.73000,28.0
44.77000,27.0
44.81000,22.0
44.85000,22.0
44.89000,18.0
44.93000,16.0
44.97000,16.0
45.01000,14.0
45.05000,12.0
45.09000,13.0
45.13000,16.0
45.17000,11.0
45.21000,10.0
45.25000,11.0
45.29000,17.0
45.33000,8.0
45.37000,8.0
45.41000,8.0
45.45000,18.0
45.49000,13.0
45.53000,17.0
45.57000,9.0
45.61000,7.0
45.65000,10.0
45.69000,7.0
45.73000,7.0
45.77000,12.0
45.81000,15.0
45.85000,8.0
45.89000,11.0
45.93000,7.0
45.97000,9.0
46.01000,14.0
46.05000,12.0
46.09000,13.0
46.13000,7.0
46.17000,11.0
46.21000,23.0
46.25000,9.0
46.29000,10.0
46.33000,9.0
46.37000,13.0
46.41000,18.0
46.45000,9.0
46.49000,7.0
46.53000,5.0
46.57000,11.0
46.61000,8.0
46.65000,13.0
46.69000,11.0
46.73000,5.0
46.77000,19.0
46.81000,8.0
46.85000,6.0
46.89000,13.0
46.93000,12.0
46.97000,21.0
47.01000,5.0
47.05000,7.0
47.09000,6.0
47.13000,8.0
47.17000,14.0
47.21000,4.0
47.25000,7.0
47.29000,2.0
47.33000,14.0
47.37000,10.0
47.41000,8.0
47.45000,11.0
47.49000,13.0
47.53000,9.0
47.57000,11.0
47.61000,14.0
47.65000,10.0
47.69000,10.0
47.73000,11.0
47.77000,7.0
47.81000,7.0
47.85000,5.0
47.89000,10.0
47.93000,17.0
47.97000,13.0
48.01000,9.0
48.05000,10.0
48.09000,5.0
48.13000,11.0
48.17000,12.0
48.21000,14.0
48.25000,12.0
48.29000,12.0
48.33000,11.0
48.37000,10.0
48.41000,9.0
48.45000,11.0
48.49000,12.0
48.53000,14.0
48.57000,12.0
48.61000,8.0
48.65000,11.0
48.69000,9.0
48.73000,10.0
48.77000,5.0
48.81000,11.0
48.85000,9.0
48.89000,10.0
48.93000,5.0
48.97000,11.0
49.01000,8.0
49.05000,11.0
49.09000,12.0
49.13000,9.0
49.17000,6.0
49.21000,9.0
49.25000,11.0
49.29000,8.0
49.33000,5.0
49.37000,12.0
49.41000,9.0
49.45000,11.0
49.49000,10.0
49.53000,12.0
49.57000,12.0
49.61000,9.0
49.65000,11.0
49.69000,9.0
49.73000,11.0
49.77000,7.0
49.81000,12.0
49.85000,6.0
49.89000,8.0
49.93000,9.0
49.97000,6.0
50.01000,9.0
50.05000,7.0
50.09000,5.0
50.13000,8.0
50.17000,7.0
50.21000,10.0
50.25000,7.0
50.29000,8.0
50.33000,11.0
50.37000,9.0
50.41000,7.0
50.45000,6.0
50.49000,7.0
50.53000,5.0
50.57000,7.0
50.61000,10.0
50.65000,7.0
50.69000,7.0
50.73000,12.0
50.77000,7.0
50.81000,13.0
50.85000,10.0
50.89000,11.0
50.93000,9.0
50.97000,7.0
51.01000,8.0
51.05000,11.0
51.09000,11.0
51.13000,11.0
51.17000,7.0
51.21000,8.0
51.25000,12.0
51.29000,9.0
51.33000,11.0
51.37000,10.0
51.41000,8.0
51.45000,16.0
51.49000,8.0
51.53000,12.0
51.57000,16.0
51.61000,8.0
51.65000,13.0
51.69000,3.0
51.73000,10.0
51.77000,14.0
51.81000,5.0
51.85000,9.0
51.89000,11.0
51.93000,11.0
51.97000,11.0
52.01000,17.0
52.05000,12.0
52.09000,17.0
52.13000,8.0
52.17000,7.0
52.21000,6.0
52.25000,9.0
52.29000,9.0
52.33000,11.0
52.37000,20.0
52.41000,8.0
52.45000,13.0
52.49000,17.0
52.53000,17.0
52.57000,16.0
52.61000,18.0
52.65000,25.0
52.69000,28.0
52.73000,35.0
52.77000,35.0
52.81000,19.0
52.85000,29.0
52.89000,27.0
52.93000,27.0
52.97000,14.0
53.01000,20.0
53.05000,22.0
53.09000,22.0
53.13000,15.0
53.17000,10.0
53.21000,17.0
53.25000,18.0
53.29000,13.0
53.33000,12.0
53.37000,15.0
53.41000,9.0
53.45000,10.0
53.49000,7.0
53.53000,14.0
53.57000,24.0
53.61000,13.0
53.65000,13.0
53.69000,10.0
53.73000,16.0
53.77000,12.0
53.81000,9.0
53.85000,15.0
53.89000,8.0
53.93000,16.0
53.97000,14.0
54.01000,14.0
54.05000,14.0
54.09000,10.0
54.13000,15.0
54.17000,12.0
54.21000,20.0
54.25000,13.0
54.29000,17.0
54.33000,10.0
54.37000,17.0
54.41000,21.0
54.45000,32.0
54.49000,19.0
54.53000,20.0
54.57000,11.0
54.61000,16.0
54.65000,12.0
54.69000,20.0
54.73000,10.0
54.77000,16.0
54.81000,16.0
54.85000,18.0
54.89000,28.0
54.93000,10.0
54.97000,10.0
55.01000,8.0
55.05000,14.0
55.09000,13.0
55.13000,17.0
55.17000,14.0
55.21000,17.0
55.25000,17.0
55.29000,23.0
55.33000,20.0
55.37000,9.0
55.41000,22.0
55.45000,17.0
55.49000,17.0
55.53000,15.0
55.57000,24.0
55.61000,31.0
55.65000,24.0
55.69000,20.0
55.73000,19.0
55.77000,32.0
55.81000,20.0
55.85000,31.0
55.89000,24.0
55.93000,28.0
55.97000,24.0
56.01000,37.0
56.05000,26.0
56.09000,22.0
56.13000,20.0
56.17000,13.0
56.21000,23.0
56.25000,20.0
56.29000,18.0
56.33000,17.0
56.37000,16.0
56.41000,17.0
56.45000,13.0
56.49000,17.0
56.53000,11.0
56.57000,13.0
56.61000,16.0
56.65000,15.0
56.69000,17.0
56.73000,10.0
56.77000,6.0
56.81000,13.0
56.85000,23.0
56.89000,10.0
56.93000,13.0
56.97000,9.0
57.01000,7.0
57.05000,14.0
57.09000,9.0
57.13000,16.0
57.17000,11.0
57.21000,8.0
57.25000,10.0
57.29000,6.0
57.33000,13.0
57.37000,11.0
57.41000,7.0
57.45000,10.0
57.49000,5.0
57.53000,10.0
57.57000,9.0
57.61000,12.0
57.65000,9.0
57.69000,9.0
57.73000,6.0
57.77000,9.0
57.81000,4.0
57.85000,9.0
57.89000,9.0
57.93000,9.0
57.97000,8.0
58.01000,9.0
58.05000,13.0
58.09000,12.0
58.13000,12.0
58.17000,8.0
58.21000,6.0
58.25000,6.0
58.29000,3.0
58.33000,8.0
58.37000,4.0
58.41000,7.0
58.45000,13.0
58.49000,11.0
58.53000,7.0
58.57000,13.0
58.61000,5.0
58.65000,15.0
58.69000,5.0
58.73000,27.0
58.77000,8.0
58.81000,7.0
58.85000,5.0
58.89000,10.0
58.93000,4.0
58.97000,10.0
59.01000,7.0
59.05000,9.0
59.09000,4.0
59.13000,2.0
59.17000,12.0
59.21000,8.0
59.25000,11.0
59.29000,10.0
59.33000,12.0
59.37000,8.0
59.41000,7.0
59.45000,7.0
59.49000,7.0
59.53000,6.0
59.57000,4.0
59.61000,10.0
59.65000,9.0
59.69000,6.0
59.73000,6.0
59.77000,7.0
59.81000,11.0
59.85000,14.0
59.89000,5.0
59.93000,9.0
59.97000,5.0
60.01000,8.0
60.05000,14.0
60.09000,11.0
60.13000,12.0
60.17000,7.0
60.21000,12.0
60.25000,4.0
60.29000,10.0
60.33000,14.0
60.37000,6.0
60.41000,5.0
60.45000,6.0
60.49000,6.0
60.53000,2.0
60.57000,9.0
60.61000,8.0
60.65000,4.0
60.69000,7.0
60.73000,7.0
60.77000,4.0
60.81000,9.0
60.85000,6.0
60.89000,10.0
60.93000,7.0
60.97000,9.0
61.01000,7.0
61.05000,11.0
61.09000,7.0
61.13000,5.0
61.17000,9.0
61.21000,7.0
61.25000,8.0
61.29000,10.0
61.33000,5.0
61.37000,13.0
61.41000,6.0
61.45000,10.0
61.49000,8.0
61.53000,8.0
61.57000,10.0
61.61000,7.0
61.65000,6.0
61.69000,7.0
61.73000,5.0
61.77000,9.0
61.81000,13.0
61.85000,9.0
61.89000,3.0
61.93000,6.0
61.97000,8.0
62.01000,6.0
62.05000,6.0
62.09000,12.0
62.13000,9.0
62.17000,9.0
62.21000,9.0
62.25000,14.0
62.29000,9.0
62.33000,10.0
62.37000,12.0
62.41000,5.0
62.45000,8.0
62.49000,11.0
62.53000,12.0
62.57000,8.0
62.61000,14.0
62.65000,11.0
62.69000,7.0
62.73000,6.0
62.77000,6.0
62.81000,7.0
62.85000,21.0
62.89000,11.0
62.93000,13.0
62.97000,14.0
63.01000,13.0
63.05000,11.0
63.09000,15.0
63.13000,12.0
63.17000,16.0
63.21000,13.0
63.25000,10.0
63.29000,14.0
63.33000,14.0
63.37000,14.0
63.41000,11.0
63.45000,13.0
63.49000,14.0
63.53000,12.0
63.57000,12.0
63.61000,17.0
63.65000,11.0
63.69000,12.0
63.73000,14.0
63.77000,16.0
63.81000,12.0
63.85000,9.0
63.89000,13.0
63.93000,20.0
63.97000,23.0
64.01000,22.0
64.05000,30.0
64.09000,23.0
64.13000,42.0
64.17000,47.0
64.21000,64.0
64.25000,45.0
64.29000,61.0
64.33000,72.0
64.37000,78.0
64.41000,75.0
64.45000,71.0
64.49000,97.0
64.53000,75.0
64.57000,77.0
64.61000,80.0
64.65000,60.0
64.69000,73.0
64.73000,51.0
64.77000,44.0
64.81000,64.0
64.85000,34.0
64.89000,32.0
64.93000,31.0
64.97000,24.0
65.01000,29.0
65.05000,28.0
65.09000,23.0
65.13000,15.0
65.17000,13.0
65.21000,19.0
65.25000,17.0
65.29000,8.0
65.33000,12.0
65.37000,19.0
65.41000,16.0
65.45000,16.0
65.49000,13.0
65.53000,9.0
65.57000,5.0
65.61000,17.0
65.65000,9.0
65.69000,5.0
65.73000,12.0
65.77000,4.0
65.81000,8.0
65.85000,4.0
65.89000,4.0
65.93000,10.0
65.97000,12.0
66.01000,2.0
66.05000,8.0
66.09000,6.0
66.13000,5.0
66.17000,12.0
66.21000,7.0
66.25000,9.0
66.29000,14.0
66.33000,9.0
66.37000,8.0
66.41000,2.0
66.45000,9.0
66.49000,6.0
66.53000,5.0
66.57000,10.0
66.61000,7.0
66.65000,13.0
66.69000,12.0
66.73000,13.0
66.77000,5.0
66.81000,6.0
66.85000,9.0
66.89000,6.0
66.93000,8.0
66.97000,11.0
67.01000,8.0
67.05000,8.0
67.09000,8.0
67.13000,10.0
67.17000,10.0
67.21000,9.0
67.25000,6.0
67.29000,8.0
67.33000,11.0
67.37000,11.0
67.41000,7.0
67.45000,7.0
67.49000,3.0
67.53000,6.0
67.57000,13.0
67.61000,6.0
67.65000,6.0
67.69000,5.0
67.73000,8.0
67.77000,6.0
67.81000,7.0
67.85000,8.0
67.89000,10.0
67.93000,9.0
67.97000,7.0
68.01000,15.0
68.05000,5.0
68.09000,7.0
68.13000,13.0
68.17000,9.0
68.21000,10.0
68.25000,5.0
68.29000,12.0
68.33000,7.0
68.37000,5.0
68.41000,10.0
68.45000,14.0
68.49000,5.0
68.53000,12.0
68.57000,7.0
68.61000,9.0
68.65000,7.0
68.69000,9.0
68.73000,6.0
68.77000,5.0
68.81000,10.0
68.85000,5.0
68.89000,8.0
68.93000,13.0
68.97000,6.0
69.01000,7.0
69.05000,12.0
69.09000,8.0
69.13000,10.0
69.17000,7.0
69.21000,5.0
69.25000,4.0
69.29000,9.0
69.33000,14.0
69.37000,12.0
69.41000,12.0
69.45000,10.0
69.49000,11.0
69.53000,7.0
69.57000,8.0
69.61000,11.0
69.65000,8.0
69.69000,6.0
69.73000,6.0
69.77000,19.0
69.81000,14.0
69.85000,10.0
69.89000,9.0
69.93000,8.0
69.97000,8.0
70.01000,9.0
70.05000,11.0
70.09000,12.0
70.13000,9.0
70.17000,7.0
70.21000,9.0
70.25000,15.0
70.29000,4.0
70.33000,17.0
70.37000,6.0
70.41000,10.0
70.45000,8.0
70.49000,10.0
70.53000,15.0
70.57000,12.0
70.61000,12.0
70.65000,10.0
70.69000,6.0
70.73000,11.0
70.77000,15.0
70.81000,14.0
70.85000,17.0
70.89000,14.0
70.93000,11.0
70.97000,14.0
71.01000,14.0
71.05000,11.0
71.09000,11.0
71.13000,17.0
71.17000,19.0
71.21000,13.0
71.25000,16.0
71.29000,5.0
71.33000,11.0
71.37000,11.0
71.41000,9.0
71.45000,9.0
71.49000,12.0
71.53000,20.0
71.57000,18.0
71.61000,6.0
71.65000,12.0
71.69000,13.0
71.73000,16.0
71.77000,11.0
71.81000,17.0
71.85000,15.0
71.89000,9.0
71.93000,13.0
71.97000,10.0
72.01000,10.0
72.05000,7.0
72.09000,8.0
72.13000,13.0
72.17000,15.0
72.21000,18.0
72.25000,18.0
72.29000,17.0
72.33000,16.0
72.37000,11.0
72.41000,14.0
72.45000,11.0
72.49000,18.0
72.53000,19.0
72.57000,18.0
72.61000,14.0
72.65000,26.0
72.69000,23.0
72.73000,30.0
72.77000,34.0
72.81000,27.0
72.85000,24.0
72.89000,37.0
72.93000,28.0
72.97000,33.0
73.01000,51.0
73.05000,50.0
73.09000,36.0
73.13000,49.0
73.17000,64.0
73.21000,88.0
73.25000,98.0
73.29000,143.0
73.33000,143.0
73.37000,152.0
73.41000,162.0
73.45000,206.0
73.49000,175.0
73.53000,218.0
73.57000,207.0
73.61000,169.0
73.65000,205.0
73.69000,189.0
73.73000,181.0
73.77000,154.0
73.81000,97.0
73.85000,97.0
73.89000,100.0
73.93000,72.0
73.97000,75.0
74.01000,58.0
74.05000,55.0
74.09000,42.0
74.13000,37.0
74.17000,42.0
74.21000,30.0
74.25000,37.0
74.29000,26.0
74.33000,18.0
74.37000,24.0
74.41000,20.0
74.45000,20.0
74.49000,20.0
74.53000,20.0
74.57000,15.0
74.61000,12.0
74.65000,14.0
74.69000,17.0
74.73000,21.0
74.77000,26.0
74.81000,13.0
74.85000,12.0
74.89000,16.0
74.93000,19.0
74.97000,9.0
75.01000,16.0
75.05000,24.0
75.09000,14.0
75.13000,15.0
75.17000,10.0
75.21000,13.0
75.25000,13.0
75.29000,17.0
75.33000,13.0
75.37000,12.0
75.41000,9.0
75.45000,11.0
75.49000,11.0
75.53000,12.0
75.57000,6.0
75.61000,22.0
75.65000,18.0
75.69000,11.0
75.73000,12.0
75.77000,5.0
75.81000,10.0
75.85000,9.0
75.89000,8.0
75.93000,8.0
75.97000,8.0
76.01000,13.0
76.05000,7.0
76.09000,10.0
76.13000,10.0
76.17000,17.0
76.21000,6.0
76.25000,8.0
76.29000,13.0
76.33000,15.0
76.37000,12.0
76.41000,8.0
76.45000,7.0
76.49000,15.0
76.53000,8.0
76.57000,13.0
76.61000,13.0
76.65000,15.0
76.69000,10.0
76.73000,8.0
76.77000,7.0
76.81000,9.0
76.85000,6.0
76.89000,9.0
76.93000,7.0
76.97000,14.0
77.01000,7.0
77.05000,2.0
77.09000,5.0
77.13000,8.0
77.17000,11.0
77.21000,12.0
77.25000,12.0
77.29000,13.0
77.33000,12.0
77.37000,8.0
77.41000,10.0
77.45000,11.0
77.49000,6.0
77.53000,13.0
77.57000,10.0
77.61000,21.0
77.65000,16.0
77.69000,8.0
77.73000,11.0
77.77000,6.0
77.81000,16.0
77.85000,13.0
77.89000,17.0
77.93000,15.0
77.97000,8.0
78.01000,10.0
78.05000,17.0
78.09000,13.0
78.13000,13.0
78.17000,12.0
78.21000,14.0
78.25000,6.0
78.29000,14.0
78.33000,9.0
78.37000,17.0
78.41000,18.0
78.45000,14.0
78.49000,19.0
78.53000,21.0
78.57000,19.0
78.61000,7.0
78.65000,13.0
78.69000,21.0
78.73000,19.0
78.77000,23.0
78.81000,30.0
78.85000,20.0
78.89000,24.0
78.93000,39.0
78.97000,27.0
79.01000,46.0
79.05000,37.0
79.09000,45.0
79.13000,60.0
79.17000,64.0
79.21000,72.0
79.25000,70.0
79.29000,75.0
79.33000,62.0
79.37000,74.0
79.41000,78.0
79.45000,68.0
79.49000,45.0
79.53000,63.0
79.57000,53.0
79.61000,61.0
79.65000,55.0
79.69000,27.0
79.73000,34.0
79.77000,36.0
79.81000,35.0
79.85000,29.0
79.89000,14.0
79.93000,20.0
79.97000,15.0
80.01000,21.0
80.05000,19.0
80.09000,14.0
80.13000,8.0
80.17000,16.0
80.21000,7.0
80.25000,9.0
80.29000,10.0
80.33000,8.0
80.37000,12.0
80.41000,11.0
80.45000,8.0
80.49000,8.0
80.53000,5.0
80.57000,11.0
80.61000,15.0
80.65000,14.0
80.69000,15.0
80.73000,4.0
80.77000,8.0
80.81000,11.0
80.85000,9.0
80.89000,8.0
80.93000,6.0
80.97000,9.0
81.01000,11.0
81.05000,14.0
81.09000,8.0
81.13000,11.0
81.17000,7.0
81.21000,5.0
81.25000,6.0
81.29000,5.0
81.33000,9.0
81.37000,9.0
81.41000,12.0
81.45000,9.0
81.49000,6.0
81.53000,6.0
81.57000,9.0
81.61000,10.0
81.65000,5.0
81.69000,13.0
81.73000,6.0
81.77000,11.0
81.81000,8.0
81.85000,10.0
81.89000,10.0
81.93000,5.0
81.97000,10.0
82.01000,6.0
82.05000,9.0
82.09000,9.0
82.13000,7.0
82.17000,10.0
82.21000,10.0
82.25000,7.0
82.29000,9.0
82.33000,7.0
82.37000,12.0
82.41000,7.0
82.45000,9.0
82.49000,9.0
82.53000,3.0
82.57000,6.0
82.61000,6.0
82.65000,8.0
82.69000,6.0
82.73000,9.0
82.77000,5.0
82.81000,6.0
82.85000,3.0
82.89000,7.0
82.93000,6.0
82.97000,4.0
83.01000,2.0
83.05000,4.0
83.09000,8.0
83.13000,4.0
83.17000,9.0
83.21000,7.0
83.25000,8.0
83.29000,4.0
83.33000,6.0
83.37000,7.0
83.41000,12.0
83.45000,8.0
83.49000,8.0
83.53000,5.0
83.57000,6.0
83.61000,7.0
83.65000,12.0
83.69000,6.0
83.73000,6.0
83.77000,6.0
83.81000,6.0
83.85000,10.0
83.89000,7.0
83.93000,12.0
83.97000,10.0
84.01000,6.0
84.05000,4.0
84.09000,3.0
84.13000,10.0
84.17000,8.0
84.21000,9.0
84.25000,8.0
84.29000,6.0
84.33000,6.0
84.37000,7.0
84.41000,7.0
84.45000,2.0
84.49000,9.0
84.53000,7.0
84.57000,5.0
84.61000,9.0
84.65000,7.0
84.69000,9.0
84.73000,6.0
84.77000,9.0
84.81000,8.0
84.85000,9.0
84.89000,4.0
84.93000,7.0
84.97000,8.0
85.01000,8.0
85.05000,10.0
85.09000,9.0
85.13000,6.0
85.17000,7.0
85.21000,5.0
85.25000,4.0
85.29000,14.0
85.33000,8.0
85.37000,8.0
85.41000,4.0
85.45000,6.0
85.49000,6.0
85.53000,7.0
85.57000,10.0
85.61000,4.0
85.65000,5.0
85.69000,9.0
85.73000,18.0
85.77000,2.0
85.81000,7.0
85.85000,3.0
85.89000,10.0
85.93000,8.0
85.97000,6.0
86.01000,11.0
86.05000,2.0
86.09000,7.0
86.13000,14.0
86.17000,9.0
86.21000,5.0
86.25000,6.0
86.29000,10.0
86.33000,3.0
86.37000,8.0
86.41000,7.0
86.45000,9.0
86.49000,7.0
86.53000,5.0
86.57000,9.0
86.61000,2.0
86.65000,9.0
86.69000,5.0
86.73000,3.0
86.77000,10.0
86.81000,7.0
86.85000,10.0
86.89000,9.0
86.93000,7.0
86.97000,10.0
87.01000,3.0
87.05000,12.0
87.09000,8.0
87.13000,2.0
87.17000,7.0
87.21000,13.0
87.25000,7.0
87.29000,8.0
87.33000,8.0
87.37000,6.0
87.41000,8.0
87.45000,5.0
87.49000,3.0
87.53000,7.0
87.57000,6.0
87.61000,10.0
87.65000,8.0
87.69000,9.0
87.73000,5.0
87.77000,10.0
87.81000,10.0
87.85000,5.0
87.89000,1.0
87.93000,6.0
87.97000,5.0
88.01000,10.0
88.05000,2.0
88.09000,3.0
88.13000,10.0
88.17000,2.0
88.21000,5.0
88.25000,11.0
88.29000,8.0
88.33000,3.0
88.37000,9.0
88.41000,7.0
88.45000,8.0
88.49000,8.0
88.53000,7.0
88.57000,7.0
88.61000,6.0
88.65000,3.0
88.69000,4.0
88.73000,8.0
88.77000,5.0
88.81000,6.0
88.85000,11.0
88.89000,5.0
88.93000,10.0
88.97000,6.0
89.01000,8.0
89.05000,6.0
89.09000,15.0
89.13000,10.0
89.17000,12.0
89.21000,10.0
89.25000,6.0
89.29000,3.0
89.33000,10.0
89.37000,9.0
89.41000,8.0
89.45000,7.0
89.49000,12.0
89.53000,17.0
89.57000,22.0
89.61000,14.0
89.65000,9.0
89.69000,12.0
89.73000,12.0
89.77000,12.0
89.81000,10.0
89.85000,15.0
89.89000,11.0
89.93000,18.0
89.97000,9.0
89.99000,12.0