File: XRD/misc/xrdml_parser/test1.xrdml
<?xml version="1.0" encoding="UTF-8"?>
<xrdMeasurements xmlns="http://www.xrdml.com/XRDMeasurement/1.3" xmlns:xsi="http://www.w3.org/2001/XMLSchema-instance" xsi:schemaLocation="http://www.xrdml.com/XRDMeasurement/1.3 http://www.xrdml.com/XRDMeasurement/1.3/XRDMeasurement.xsd" status="Completed">
	<comment>
		<entry>Configuration=Anton Paar XRK-900, Owner=User-1, Creation date=3/23/2007 13:26:42</entry>
		<entry>Goniometer=PW3050/60 (Theta/Theta); Minimum step size 2Theta:0.001; Minimum step size Omega:0.001</entry>
		<entry>Sample stage=Anton Paar XRK-900</entry>
		<entry>Diffractometer system=XPERT-PRO</entry>
		<entry>Measurement program=Co2FeGa_10-120-1h, Owner=User-1, Creation date=2/20/2018 10:39:49</entry>
	</comment>
	<sample type="To be analyzed">
		<id></id>
		<name></name>
		<preparedBy></preparedBy>
	</sample>
	<xrdMeasurement measurementType="Scan" status="Completed" sampleMode="Reflection">
		<comment>
			<entry>1h 10-120</entry>
		</comment>
		<usedWavelength intended="K-Alpha 1">
			<kAlpha1 unit="Angstrom">1.5405980</kAlpha1>
			<kAlpha2 unit="Angstrom">1.5444260</kAlpha2>
			<kBeta unit="Angstrom">1.3922500</kBeta>
			<ratioKAlpha2KAlpha1>0.5000</ratioKAlpha2KAlpha1>
		</usedWavelength>
		<incidentBeamPath>
			<radius unit="mm">240.00</radius>
			<xRayTube id="1010048" name="PW3373/10 Cu LFF DK174172">
				<tension unit="kV">45</tension>
				<current unit="mA">40</current>
				<anodeMaterial>Cu</anodeMaterial>
				<focus type="Line">
					<length unit="mm">12.0</length>
					<width unit="mm">0.4</width>
					<takeOffAngle unit="deg">6.0</takeOffAngle>
				</focus>
			</xRayTube>
			<sollerSlit id="21010002" name="Soller 0.04 rad.">
				<opening unit="rad">0.0400</opening>
			</sollerSlit>
			<mask id="22080002" name="Inc. Mask Fixed  10 mm (MPD/MRD)">
				<width unit="mm">6.60</width>
			</mask>
			<antiScatterSlit id="22010001" name="Slit Fixed 4Â°" xsi:type="fixedAntiScatterSlitType">
				<height unit="mm">5.88</height>
			</antiScatterSlit>
			<divergenceSlit id="22010012" name="Prog. Div. Slit" xsi:type="automaticDivergenceSlitType">
				<distanceToSample unit="mm">140.00</distanceToSample>
				<irradiatedLength unit="mm">10.0</irradiatedLength>
				<offset unit="mm">0.00</offset>
			</divergenceSlit>
		</incidentBeamPath>
		<diffractedBeamPath>
			<radius unit="mm">240.00</radius>
			<antiScatterSlit id="22110008" name="AS Slit 10.4 mm (PIXcel &amp; Monochromator)" xsi:type="fixedAntiScatterSlitType">
				<height unit="mm">10.40</height>
			</antiScatterSlit>
			<monochromator id="23010033" name="Diffr. Beam Flat 1x graphite for Cu (PIXcel)" hybrid="false">
				<crystal type="Symmetric" shape="Flat">C</crystal>
				<numberOfReflections>1</numberOfReflections>
				<hkl>
					<h>0</h>
					<k>0</k>
					<l>2</l>
				</hkl>
			</monochromator>
			<detector id="7010015" name="PIXcel" xsi:type="rtmsDetectorType">
				<phd>
					<lowerLevel unit="%">25.5</lowerLevel>
					<upperLevel unit="%">70.0</upperLevel>
				</phd>
				<mode>Scanning</mode>
				<activeLength unit="deg">3.347</activeLength>
			</detector>
		</diffractedBeamPath>
		<scan appendNumber="0" mode="Continuous" scanAxis="Gonio" status="Completed">
			<header>
				<startTimeStamp>2018-02-21T01:14:47+01:00</startTimeStamp>
				<endTimeStamp>2018-02-21T02:16:54+01:00</endTimeStamp>
				<author>
					<name>Cinf PC RJ</name>
				</author>
				<source>
					<applicationSoftware version="2.2a">X'Pert Data Collector</applicationSoftware>
					<instrumentControlSoftware version="2.1E">XPERT-PRO</instrumentControlSoftware>
					<instrumentID>0000000011020749</instrumentID>
				</source>
			</header>
			<dataPoints>
				<positions axis="2Theta" unit="deg">
					<startPosition>10.04726056</startPosition>
					<endPosition>119.97397991</endPosition>
				</positions>
				<positions axis="Omega" unit="deg">
					<startPosition>5.02363028</startPosition>
					<endPosition>59.98698995</endPosition>
				</positions>
				<commonCountingTime unit="seconds">439.875</commonCountingTime>
				<intensities unit="counts">359 338 323 313 286 306 330 307 317 314 325 314 309 319 316 319 332 337 359 281 345 333 290 293 352 317 308 319 318 309 342 307 299 324 298 314 290 356 282 300 300 346 341 360 289 291 331 312 301 353 328 278 339 314 298 315 297 310 341 323 305 316 336 307 332 292 276 297 315 293 343 322 328 307 303 307 342 315 317 350 317 317 310 327 368 314 375 320 360 313 359 375 325 346 330 339 328 334 320 352 392 369 381 375 360 412 380 372 382 421 366 377 423 401 402 394 445 401 465 456 439 457 430 487 488 501 526 497 467 472 447 508 451 527 524 489 504 549 529 494 553 490 557 559 593 570 618 559 572 594 595 652 600 600 623 646 639 632 665 687 684 679 670 695 692 683 651 726 756 807 765 752 813 798 774 809 873 810 849 944 869 802 850 951 911 936 910 863 971 918 911 928 979 907 1071 1026 961 1026 980 1033 991 996 1117 1093 1024 1073 1089 1080 1084 1132 1087 1166 1122 1164 1084 1067 1137 1204 1040 1178 1189 1155 1123 1209 1133 1102 1179 1184 1114 1143 1164 1241 1199 1209 1154 1190 1186 1181 1114 1136 1111 1134 1131 1174 1126 1156 1080 1142 1119 1145 1127 1077 1024 1160 1074 1104 1103 1069 1056 1047 1109 996 1025 1012 1094 1104 1076 1063 1054 1076 1046 1070 1032 1042 1011 1058 1037 996 971 1047 928 928 963 980 1032 902 963 982 927 1029 954 924 980 951 989 937 918 938 976 875 887 947 951 931 939 936 973 972 950 890 892 922 861 944 946 853 930 939 907 928 903 889 853 813 816 824 857 850 862 894 850 848 842 795 807 853 812 833 784 790 856 801 874 792 788 804 855 784 845 801 808 825 876 795 838 761 784 806 817 808 758 785 737 758 797 758 760 758 756 813 812 810 777 791 814 815 811 758 834 752 746 809 780 746 793 730 800 780 834 805 780 765 811 788 833 747 711 750 811 772 764 812 779 804 778 801 800 790 726 759 770 720 782 724 763 791 758 743 748 785 746 710 734 820 755 786 782 693 684 738 781 722 812 773 775 768 720 744 708 796 742 736 766 789 771 715 766 820 800 734 722 753 733 762 765 784 767 771 728 795 831 783 768 713 738 708 677 731 761 790 709 748 777 715 674 685 745 749 798 744 727 727 769 793 719 787 775 812 725 714 769 741 754 714 753 722 725 737 702 748 760 699 692 762 730 735 704 780 775 772 813 770 796 751 698 739 734 711 706 734 721 735 730 728 749 703 718 735 737 780 747 726 764 752 720 719 715 676 729 728 777 753 731 753 762 789 763 742 698 738 727 783 779 708 739 744 712 761 717 766 785 735 775 757 748 751 693 787 714 714 743 728 762 778 836 753 760 786 748 733 765 764 724 770 765 759 752 811 807 784 764 799 848 841 841 909 836 765 828 839 853 831 847 892 856 890 832 881 963 953 937 943 958 943 982 985 972 1055 1016 1044 1111 1158 1099 1114 1118 1100 1105 1176 1121 1216 1269 1187 1191 1243 1294 1343 1430 1468 1561 1506 1571 1642 1712 1693 1896 1910 1981 2096 2045 2178 2249 2276 2237 2330 2453 2311 2413 2368 2518 2382 2275 2200 2210 2153 2139 1892 1957 1810 1809 1660 1626 1544 1482 1422 1346 1359 1276 1275 1204 1196 1111 1182 1135 1124 1021 1049 985 1019 995 976 1015 944 859 960 947 963 889 933 889 914 870 901 914 912 947 879 941 882 871 924 926 868 882 893 895 880 895 923 832 928 887 851 884 858 910 880 842 889 886 823 853 898 844 891 910 877 899 871 823 871 881 879 869 877 867 816 862 880 864 864 884 913 885 830 829 846 917 896 858 909 818 918 827 899 866 887 880 932 837 914 919 873 938 871 902 885 868 869 868 947 958 881 875 879 914 864 893 891 885 871 819 849 844 836 838 896 834 848 864 810 850 904 820 853 887 840 833 808 796 815 819 874 833 824 847 847 828 814 830 874 853 821 809 833 826 779 844 833 889 804 872 820 794 861 811 835 809 820 816 864 832 850 819 881 784 854 821 864 862 861 890 834 866 819 858 868 830 823 857 826 900 804 865 839 842 907 908 829 887 895 891 884 894 865 848 881 848 877 823 881 865 829 833 888 902 866 897 844 902 864 876 929 834 858 866 882 832 893 892 839 877 881 923 908 905 854 849 893 877 906 856 926 972 911 919 916 927 865 870 841 943 899 937 885 884 842 928 914 915 940 943 913 928 868 927 925 901 910 975 904 900 920 962 968 992 858 922 956 951 971 1004 941 972 959 957 896 927 955 961 1007 969 933 963 937 988 995 930 929 955 958 963 985 984 954 1003 952 965 961 959 1052 917 980 996 1059 971 1032 1041 1044 990 1064 1016 995 1034 1078 942 1028 974 1079 1022 943 987 1079 984 1062 1055 974 1010 1038 967 1035 1016 1061 1005 1007 1035 1034 1104 1097 1036 1090 1045 1008 1109 1130 1028 1172 1084 1119 1141 1093 1160 1143 1240 1187 1233 1269 1258 1196 1204 1253 1263 1281 1326 1258 1202 1345 1268 1348 1242 1294 1236 1230 1200 1261 1193 1187 1219 1192 1172 1184 1179 1095 1122 1119 1116 1157 1130 1104 1124 1026 989 1099 1040 1021 1109 1033 1065 1092 1130 1119 1026 1031 1020 1034 1091 1069 1095 1035 1049 1078 1065 957 1060 1051 1076 1051 1114 1049 1029 1082 990 1049 990 1011 1007 1058 1074 1018 1081 1062 1078 1082 1023 1089 1034 1044 1082 1061 1019 1043 1017 1010 1149 1022 1013 1082 1045 1090 993 1014 1076 1022 1014 1061 1050 1011 1101 1017 1059 1204 1010 1047 1036 1143 1074 1112 1066 1107 1037 1093 1065 1030 1069 1119 1061 1044 1128 1084 1130 1140 1067 1106 1075 1084 1047 1050 1054 1123 1043 1080 1141 1033 1084 1156 1097 1110 1039 1089 1085 1059 1162 1070 1145 1092 1110 1036 1108 1059 1087 1066 1115 1075 1137 1107 1087 1070 1138 1087 1086 1106 1092 1072 1079 1136 1147 1050 1126 1164 1111 1168 1105 1098 1057 1166 1142 1095 1078 1068 1083 1133 1143 1163 1219 1080 1168 1159 1161 1142 1116 1137 1162 1163 1147 1099 1202 1149 1140 1118 1171 1090 1115 1138 1100 1188 1153 1168 1198 1170 1198 1127 1203 1168 1128 1165 1177 1188 1104 1145 1153 1144 1077 1104 1083 1157 1146 1101 1172 1133 1156 1152 1185 1153 1147 1098 1103 1172 1165 1081 1148 1160 1136 1171 1173 1196 1145 1134 1151 1110 1199 1191 1163 1096 1144 1116 1171 1191 1199 1229 1224 1134 1199 1088 1200 1165 1116 1184 1190 1245 1168 1124 1229 1140 1197 1115 1144 1186 1129 1116 1140 1147 1147 1181 1134 1161 1083 1126 1161 1132 1146 1119 1113 1150 1160 1155 1134 1159 1133 1189 1092 1160 1045 1152 1163 1132 1152 1154 1212 1176 1212 1199 1192 1215 1270 1233 1319 1196 1240 1258 1277 1361 1347 1384 1321 1368 1427 1385 1383 1411 1463 1452 1540 1428 1582 1521 1511 1498 1481 1560 1518 1559 1480 1533 1474 1457 1460 1362 1401 1413 1373 1335 1328 1228 1192 1253 1245 1242 1230 1200 1216 1212 1141 1165 1128 1083 1116 1154 1156 1145 1111 1091 1048 1031 1030 1022 1009 1044 1025 1014 926 971 977 1027 1035 935 1017 1062 956 1009 965 984 973 992 936 1003 953 967 966 986 953 989 989 1014 981 935 876 982 972 974 952 945 932 905 974 979 932 906 954 907 990 976 911 903 951 861 925 944 895 921 946 927 967 981 964 919 963 947 927 907 961 937 895 937 903 910 994 903 891 902 925 915 935 933 950 913 912 933 1061 942 890 888 896 918 927 915 970 894 961 946 918 1008 930 917 914 953 910 946 897 926 936 886 919 924 889 1009 970 967 887 922 972 1006 962 893 956 1027 1000 949 891 993 940 910 965 970 1016 1026 970 961 973 968 978 1015 985 976 922 903 964 1017 971 944 953 1000 939 966 943 979 1030 964 898 919 887 931 957 1005 922 915 948 941 1017 920 942 999 1003 987 981 976 969 992 1000 1000 968 902 925 953 983 961 904 856 974 960 1009 992 946 912 921 955 946 936 997 947 1003 980 982 919 966 917 985 939 900 969 969 949 955 966 967 956 932 961 1086 1027 1041 1014 897 961 944 943 960 1031 968 958 983 917 1010 1029 920 1012 942 1006 945 995 1031 944 1054 1047 982 979 1067 968 1086 983 1049 985 931 953 1031 958 1016 936 1042 992 1058 1071 1013 1059 967 1056 1073 1065 1084 1061 1040 1046 1050 1053 1136 1075 1089 1116 1083 1128 1163 1109 1102 1162 1136 1207 1096 1150 1107 1169 1154 1087 1224 1117 1083 1212 1123 1107 1075 1104 1051 1085 1049 1128 1067 1076 1061 1048 1111 1111 1077 1111 1060 1120 1010 1039 1036 1072 1002 1038 1058 1051 1053 1074 964 963 1041 969 1055 1045 1030 1033 1040 1026 1053 1050 1045 980 1032 1052 1083 998 1069 995 949 1060 1057 1032 1019 1014 1056 1009 1040 1043 1022 1002 959 973 973 1035 1037 995 1057 1039 1025 1051 1001 1063 1073 1031 1049 1059 1098 1082 1015 1074 975 1023 1027 1097 1088 1068 1062 987 1093 1102 1077 1130 1030 1135 1032 1115 1038 1065 1116 1048 1005 1063 1060 1099 1102 1101 1053 1058 1053 1088 1113 1084 1111 1100 1088 1155 1073 1045 1082 1098 1067 1075 1132 1083 1016 1107 1101 1021 1067 1134 1159 988 1044 1157 1033 1078 1069 966 986 1121 1137 1050 1087 1058 1109 1108 1080 968 1123 1096 1060 1106 1078 1093 1102 1069 1078 1115 1141 1082 1069 1120 1091 1092 1080 1055 1086 1045 1147 1166 1071 1077 1078 1089 1111 1024 1103 1109 993 1094 1046 1063 1093 1098 1115 1116 1065 1133 1080 1071 1101 1036 1100 1102 1097 1075 1068 1082 1117 1144 1123 1069 1100 1082 1096 1139 1060 1133 1108 1098 1129 1087 1104 1131 1124 1106 1112 1135 1080 1110 1046 1081 1042 1044 1065 1066 1079 1078 1156 1090 1086 1162 1094 1120 1070 1130 1151 1074 1098 1125 1137 1090 1126 1161 1099 1085 1107 1177 1099 1138 1116 1103 1103 1062 1162 1137 1098 1048 1116 1058 1110 1091 1105 1130 1145 1145 1132 1129 1127 1123 1146 1133 1081 1123 1094 1090 1122 1109 1136 1106 1178 1131 1144 1159 1095 1187 1194 1124 1158 1183 1186 1219 1184 1169 1203 1116 1236 1250 1146 1242 1284 1269 1252 1265 1247 1275 1267 1245 1281 1227 1281 1285 1338 1359 1393 1343 1246 1313 1333 1401 1303 1417 1367 1381 1280 1344 1373 1359 1330 1395 1327 1334 1302 1384 1452 1323 1307 1337 1270 1314 1266 1321 1408 1319 1253 1266 1286 1290 1297 1271 1264 1213 1309 1296 1214 1166 1228 1241 1210 1212 1176 1272 1249 1160 1203 1198 1178 1197 1200 1156 1154 1176 1159 1246 1150 1117 1206 1133 1142 1181 1158 1109 1160 1130 1169 1216 1159 1132 1183 1135</intensities>
			</dataPoints>
			<nonAmbientPoints type="Temperature" unit="K">
				<measurementTimes unit="seconds" deltaTime="1">0 1356 1357 3726</measurementTimes>
				<nonAmbientValues>297 297 298 298</nonAmbientValues>
			</nonAmbientPoints>
		</scan>
	</xrdMeasurement>
</xrdMeasurements>